Workbook
Name UPDATE: 'Data Sheet'!$E$1

Sheet Quarters
A1: =#REF! -> #REF! | E1: =UPDATE | J1: SCREENER.IN
A3: Narration | B3: ='Data Sheet'!B41 -> 45199 | C3: ='Data Sheet'!C41 -> 45291 | D3: ='Data Sheet'!D41 -> 45382 | E3: ='Data Sheet'!E41 -> 45473 | F3: ='Data Sheet'!F41 -> 45565 | G3: ='Data Sheet'!G41 -> 45657 | H3: ='Data Sheet'!H41 -> 45747 | I3: ='Data Sheet'!I41 -> 45838 | ... K3: ='Data Sheet'!K41 -> 46022
A4: Sales | B4: ='Data Sheet'!B42 -> 1507.02 | C4: ='Data Sheet'!C42 -> 1788.8 | D4: ='Data Sheet'!D42 -> 1667.98 | E4: ='Data Sheet'!E42 -> 1746.11 | F4: ='Data Sheet'!F42 -> 1874.74 | G4: ='Data Sheet'!G42 -> 2267.21 | H4: ='Data Sheet'!H42 -> 2061.76 | I4: ='Data Sheet'!I42 -> 2154.94 | ... K4: ='Data Sheet'!K42 -> 2873.26
A5: Expenses | B5: ='Data Sheet'!B43 -> 1426.39 | C5: ='Data Sheet'!C43 -> 1690.02 | D5: ='Data Sheet'!D43 -> 1574.7 | E5: ='Data Sheet'!E43 -> 1649.99 | F5: ='Data Sheet'!F43 -> 1771.08 | G5: ='Data Sheet'!G43 -> 2126.43 | H5: ='Data Sheet'!H43 -> 1928.41 | I5: ='Data Sheet'!I43 -> 2014.26 | ... K5: ='Data Sheet'!K43 -> 2643.5
A6: Operating Profit | B6: ='Data Sheet'!B50 -> 80.63 | C6: ='Data Sheet'!C50 -> 98.78 | D6: ='Data Sheet'!D50 -> 93.28 | E6: ='Data Sheet'!E50 -> 96.12 | F6: ='Data Sheet'!F50 -> 103.66 | G6: ='Data Sheet'!G50 -> 140.78 | H6: ='Data Sheet'!H50 -> 133.35 | I6: ='Data Sheet'!I50 -> 140.68 | ... K6: ='Data Sheet'!K50 -> 229.76
A7: Other Income | B7: ='Data Sheet'!B44 -> 8.57 | C7: ='Data Sheet'!C44 -> 7.58 | D7: ='Data Sheet'!D44 -> 7.06 | E7: ='Data Sheet'!E44 -> 7.33 | F7: ='Data Sheet'!F44 -> 5.45 | G7: ='Data Sheet'!G44 -> 5.53 | H7: ='Data Sheet'!H44 -> 8.95 | I7: ='Data Sheet'!I44 -> 9.33 | ... K7: ='Data Sheet'!K44 -> -10.1
A8: Depreciation | B8: ='Data Sheet'!B45 -> 54.64 | C8: ='Data Sheet'!C45 -> 58.03 | D8: ='Data Sheet'!D45 -> 59.65 | E8: ='Data Sheet'!E45 -> 60.06 | F8: ='Data Sheet'!F45 -> 63.62 | G8: ='Data Sheet'!G45 -> 69.82 | H8: ='Data Sheet'!H45 -> 72.9 | I8: ='Data Sheet'!I45 -> 76.14 | ... K8: ='Data Sheet'!K45 -> 80.88
A9: Interest | B9: ='Data Sheet'!B46 -> 21.31 | C9: ='Data Sheet'!C46 -> 21.84 | D9: ='Data Sheet'!D46 -> 21.13 | E9: ='Data Sheet'!E46 -> 21.31 | F9: ='Data Sheet'!F46 -> 24.23 | G9: ='Data Sheet'!G46 -> 31.93 | H9: ='Data Sheet'!H46 -> 29.85 | I9: ='Data Sheet'!I46 -> 30.16 | ... K9: ='Data Sheet'!K46 -> 29.16
A10: Profit before tax | B10: ='Data Sheet'!B47 -> 13.25 | C10: ='Data Sheet'!C47 -> 26.49 | D10: ='Data Sheet'!D47 -> 19.56 | E10: ='Data Sheet'!E47 -> 22.08 | F10: ='Data Sheet'!F47 -> 21.26 | G10: ='Data Sheet'!G47 -> 44.56 | H10: ='Data Sheet'!H47 -> 39.55 | I10: ='Data Sheet'!I47 -> 43.71 | ... K10: ='Data Sheet'!K47 -> 109.62
A11: Tax | B11: ='Data Sheet'!B48 -> 3.97 | C11: ='Data Sheet'!C48 -> 8.26 | D11: ='Data Sheet'!D48 -> 9.83 | E11: ='Data Sheet'!E48 -> 7.84 | F11: ='Data Sheet'!F48 -> 7.82 | G11: ='Data Sheet'!G48 -> 17.59 | H11: ='Data Sheet'!H48 -> 20.5 | I11: ='Data Sheet'!I48 -> 19.24 | ... K11: ='Data Sheet'!K48 -> 41.88
A12: Net profit | B12: ='Data Sheet'!B49 -> 5.85 | C12: ='Data Sheet'!C49 -> 16.19 | D12: ='Data Sheet'!D49 -> 6.93 | E12: ='Data Sheet'!E49 -> 9.64 | F12: ='Data Sheet'!F49 -> 10.04 | G12: ='Data Sheet'!G49 -> 26.12 | H12: ='Data Sheet'!H49 -> 20.28 | I12: ='Data Sheet'!I49 -> 23.32 | ... K12: ='Data Sheet'!K49 -> 63.31
A14: OPM | B14: =IF(B4>0,B6/B4,"") -> 0.05350294 | C14: =IF(C4>0,C6/C4,"") -> 0.055221377 | D14: =IF(D4>0,D6/D4,"") -> 0.055923932 | E14: =IF(E4>0,E6/E4,"") -> 0.055048078 | F14: =IF(F4>0,F6/F4,"") -> 0.055293001 | G14: =IF(G4>0,G6/G4,"") -> 0.062093939 | H14: =IF(H4>0,H6/H4,"") -> 0.064677751 | I14: =IF(I4>0,I6/I4,"") -> 0.06528256 | ... K14: =IF(K4>0,K6/K4,"") -> 0.079964918

Sheet Balance Sheet
A1: =#REF! -> #REF! | E1: =UPDATE | J1: SCREENER.IN
A3: Narration | B3: ='Data Sheet'!B56 -> 0 | C3: ='Data Sheet'!C56 -> 0 | D3: ='Data Sheet'!D56 -> 43190 | E3: ='Data Sheet'!E56 -> 43555 | F3: ='Data Sheet'!F56 -> 43921 | G3: ='Data Sheet'!G56 -> 44286 | H3: ='Data Sheet'!H56 -> 44651 | I3: ='Data Sheet'!I56 -> 45016 | ... K3: ='Data Sheet'!K56 -> 45747
A4: Equity Share Capital | B4: ='Data Sheet'!B57 -> 0 | C4: ='Data Sheet'!C57 -> 0 | D4: ='Data Sheet'!D57 -> 13.56 | E4: ='Data Sheet'!E57 -> 14.24 | F4: ='Data Sheet'!F57 -> 14.55 | G4: ='Data Sheet'!G57 -> 15.06 | H4: ='Data Sheet'!H57 -> 47.41 | I4: ='Data Sheet'!I57 -> 285.25 | ... K4: ='Data Sheet'!K57 -> 285.93
A5: Reserves | B5: ='Data Sheet'!B58 -> 0 | C5: ='Data Sheet'!C58 -> 0 | D5: ='Data Sheet'!D58 -> 108.03 | E5: ='Data Sheet'!E58 -> 216.32 | F5: ='Data Sheet'!F58 -> 307.4 | G5: ='Data Sheet'!G58 -> 474.51 | H5: ='Data Sheet'!H58 -> 1292.49 | I5: ='Data Sheet'!I58 -> 1092.77 | ... K5: ='Data Sheet'!K58 -> 1015.35
A6: Borrowings | B6: ='Data Sheet'!B59 -> 0 | C6: ='Data Sheet'!C59 -> 0 | D6: ='Data Sheet'!D59 -> 83.05 | E6: ='Data Sheet'!E59 -> 310.47 | F6: ='Data Sheet'!F59 -> 412.77 | G6: ='Data Sheet'!G59 -> 333 | H6: ='Data Sheet'!H59 -> 592.62 | I6: ='Data Sheet'!I59 -> 798.5 | ... K6: ='Data Sheet'!K59 -> 1320.59
A7: Other Liabilities | B7: ='Data Sheet'!B60 -> 0 | C7: ='Data Sheet'!C60 -> 0 | D7: ='Data Sheet'!D60 -> 148.5 | E7: ='Data Sheet'!E60 -> 234.62 | F7: ='Data Sheet'!F60 -> 389.76 | G7: ='Data Sheet'!G60 -> 479.37 | H7: ='Data Sheet'!H60 -> 713.52 | I7: ='Data Sheet'!I60 -> 773.45 | ... K7: ='Data Sheet'!K60 -> 1357.66
A8: Total | B8: ='Data Sheet'!B61 -> 0 | C8: ='Data Sheet'!C61 -> 0 | D8: ='Data Sheet'!D61 -> 353.14 | E8: ='Data Sheet'!E61 -> 775.65 | F8: ='Data Sheet'!F61 -> 1124.48 | G8: ='Data Sheet'!G61 -> 1301.94 | H8: ='Data Sheet'!H61 -> 2646.04 | I8: ='Data Sheet'!I61 -> 2949.97 | ... K8: ='Data Sheet'!K61 -> 3979.53
A10: Net Block | B10: ='Data Sheet'!B62 -> 0 | C10: ='Data Sheet'!C62 -> 0 | D10: ='Data Sheet'!D62 -> 34.12 | E10: ='Data Sheet'!E62 -> 139.58 | F10: ='Data Sheet'!F62 -> 227.03 | G10: ='Data Sheet'!G62 -> 231.13 | H10: ='Data Sheet'!H62 -> 483.25 | I10: ='Data Sheet'!I62 -> 698.82 | ... K10: ='Data Sheet'!K62 -> 834.82
A11: Capital Work in Progress | B11: ='Data Sheet'!B63 -> 0 | C11: ='Data Sheet'!C63 -> 0 | D11: ='Data Sheet'!D63 -> 0.44 | E11: ='Data Sheet'!E63 -> 0.32 | F11: ='Data Sheet'!F63 -> 2.02 | G11: ='Data Sheet'!G63 -> 2.36 | H11: ='Data Sheet'!H63 -> 24.5 | I11: ='Data Sheet'!I63 -> 30.88 | ... K11: ='Data Sheet'!K63 -> 36.74
A12: Investments | B12: ='Data Sheet'!B64 -> 0 | C12: ='Data Sheet'!C64 -> 0 | D12: ='Data Sheet'!D64 -> 10.42 | E12: ='Data Sheet'!E64 -> 138.27 | F12: ='Data Sheet'!F64 -> 3.8 | G12: ='Data Sheet'!G64 -> 1.32 | H12: ='Data Sheet'!H64 -> 0 | I12: ='Data Sheet'!I64 -> 38.12 | ... K12: ='Data Sheet'!K64 -> 0.16
A13: Other Assets | B13: ='Data Sheet'!B65 -> 0 | C13: ='Data Sheet'!C65 -> 0 | D13: ='Data Sheet'!D65 -> 308.16 | E13: ='Data Sheet'!E65 -> 497.48 | F13: ='Data Sheet'!F65 -> 891.63 | G13: ='Data Sheet'!G65 -> 1067.13 | H13: ='Data Sheet'!H65 -> 2138.29 | I13: ='Data Sheet'!I65 -> 2182.15 | ... K13: ='Data Sheet'!K65 -> 3107.81
A14: Total | B14: ='Data Sheet'!B66 -> 0 | C14: ='Data Sheet'!C66 -> 0 | D14: ='Data Sheet'!D66 -> 353.14 | E14: ='Data Sheet'!E66 -> 775.65 | F14: ='Data Sheet'!F66 -> 1124.48 | G14: ='Data Sheet'!G66 -> 1301.94 | H14: ='Data Sheet'!H66 -> 2646.04 | I14: ='Data Sheet'!I66 -> 2949.97 | ... K14: ='Data Sheet'!K66 -> 3979.53
A16: Working Capital | B16: =B13-B7 -> 0 | C16: =C13-C7 -> 0 | D16: =D13-D7 -> 159.66 | E16: =E13-E7 -> 262.86 | F16: =F13-F7 -> 501.87 | G16: =G13-G7 -> 587.76 | H16: =H13-H7 -> 1424.77 | I16: =I13-I7 -> 1408.7 | ... K16: =K13-K7 -> 1750.15
A17: Debtors | B17: ='Data Sheet'!B67 -> 0 | C17: ='Data Sheet'!C67 -> 0 | D17: ='Data Sheet'!D67 -> 70.24 | E17: ='Data Sheet'!E67 -> 57.92 | F17: ='Data Sheet'!F67 -> 98.43 | G17: ='Data Sheet'!G67 -> 76.64 | H17: ='Data Sheet'!H67 -> 94.53 | I17: ='Data Sheet'!I67 -> 163.53 | ... K17: ='Data Sheet'!K67 -> 246.61
A18: Inventory | B18: ='Data Sheet'!B68 -> 0 | C18: ='Data Sheet'!C68 -> 0 | D18: ='Data Sheet'!D68 -> 117.72 | E18: ='Data Sheet'!E68 -> 244.6 | F18: ='Data Sheet'!F68 -> 445.34 | G18: ='Data Sheet'!G68 -> 498.09 | H18: ='Data Sheet'!H68 -> 875.62 | I18: ='Data Sheet'!I68 -> 1005.14 | ... K18: ='Data Sheet'!K68 -> 1417.54
A20: Debtor Days | B20: =IF(#REF!>0,'Balance Sheet'!B17/(#REF!/365),0) -> #REF! | C20: =IF(#REF!>0,'Balance Sheet'!C17/(#REF!/365),0) -> #REF! | D20: =IF(#REF!>0,'Balance Sheet'!D17/(#REF!/365),0) -> #REF! | E20: =IF(#REF!>0,'Balance Sheet'!E17/(#REF!/365),0) -> #REF! | F20: =IF(#REF!>0,'Balance Sheet'!F17/(#REF!/365),0) -> #REF! | G20: =IF(#REF!>0,'Balance Sheet'!G17/(#REF!/365),0) -> #REF! | H20: =IF(#REF!>0,'Balance Sheet'!H17/(#REF!/365),0) -> #REF! | I20: =IF(#REF!>0,'Balance Sheet'!I17/(#REF!/365),0) -> #REF! | ... K20: =IF(#REF!>0,'Balance Sheet'!K17/(#REF!/365),0) -> #REF!
A21: Inventory Turnover | B21: =IF('Balance Sheet'!B18>0,#REF!/'Balance Sheet'!B18,0) -> 0 | C21: =IF('Balance Sheet'!C18>0,#REF!/'Balance Sheet'!C18,0) -> 0 | D21: =IF('Balance Sheet'!D18>0,#REF!/'Balance Sheet'!D18,0) -> #REF! | E21: =IF('Balance Sheet'!E18>0,#REF!/'Balance Sheet'!E18,0) -> #REF! | F21: =IF('Balance Sheet'!F18>0,#REF!/'Balance Sheet'!F18,0) -> #REF! | G21: =IF('Balance Sheet'!G18>0,#REF!/'Balance Sheet'!G18,0) -> #REF! | H21: =IF('Balance Sheet'!H18>0,#REF!/'Balance Sheet'!H18,0) -> #REF! | I21: =IF('Balance Sheet'!I18>0,#REF!/'Balance Sheet'!I18,0) -> #REF! | ... K21: =IF('Balance Sheet'!K18>0,#REF!/'Balance Sheet'!K18,0) -> #REF!
A23: Return on Equity | B23: =IF(SUM('Balance Sheet'!B4:B5)>0,#REF!/SUM('Balance Sheet'!B4:B5),"") | C23: =IF(SUM('Balance Sheet'!C4:C5)>0,#REF!/SUM('Balance Sheet'!C4:C5),"") | D23: =IF(SUM('Balance Sheet'!D4:D5)>0,#REF!/SUM('Balance Sheet'!D4:D5),"") -> #REF! | E23: =IF(SUM('Balance Sheet'!E4:E5)>0,#REF!/SUM('Balance Sheet'!E4:E5),"") -> #REF! | F23: =IF(SUM('Balance Sheet'!F4:F5)>0,#REF!/SUM('Balance Sheet'!F4:F5),"") -> #REF! | G23: =IF(SUM('Balance Sheet'!G4:G5)>0,#REF!/SUM('Balance Sheet'!G4:G5),"") -> #REF! | H23: =IF(SUM('Balance Sheet'!H4:H5)>0,#REF!/SUM('Balance Sheet'!H4:H5),"") -> #REF! | I23: =IF(SUM('Balance Sheet'!I4:I5)>0,#REF!/SUM('Balance Sheet'!I4:I5),"") -> #REF! | ... K23: =IF(SUM('Balance Sheet'!K4:K5)>0,#REF!/SUM('Balance Sheet'!K4:K5),"") -> #REF!
A24: Return on Capital Emp | C24: =IF((B4+B5+B6+C4+C5+C6)>0,(#REF!+#REF!)*2/(B4+B5+B6+C4+C5+C6),"") | D24: =IF((C4+C5+C6+D4+D5+D6)>0,(#REF!+#REF!)*2/(C4+C5+C6+D4+D5+D6),"") -> #REF! | E24: =IF((D4+D5+D6+E4+E5+E6)>0,(#REF!+#REF!)*2/(D4+D5+D6+E4+E5+E6),"") -> #REF! | F24: =IF((E4+E5+E6+F4+F5+F6)>0,(#REF!+#REF!)*2/(E4+E5+E6+F4+F5+F6),"") -> #REF! | G24: =IF((F4+F5+F6+G4+G5+G6)>0,(#REF!+#REF!)*2/(F4+F5+F6+G4+G5+G6),"") -> #REF! | H24: =IF((G4+G5+G6+H4+H5+H6)>0,(#REF!+#REF!)*2/(G4+G5+G6+H4+H5+H6),"") -> #REF! | I24: =IF((H4+H5+H6+I4+I5+I6)>0,(#REF!+#REF!)*2/(H4+H5+H6+I4+I5+I6),"") -> #REF! | J24: =IF((I4+I5+I6+J4+J5+J6)>0,(#REF!+#REF!)*2/(I4+I5+I6+J4+J5+J6),"") -> #REF! | K24: =IF((J4+J5+J6+K4+K5+K6)>0,(#REF!+#REF!)*2/(J4+J5+J6+K4+K5+K6),"") -> #REF!

Sheet Cash Flow
A1: ='Balance Sheet'!A1 -> #REF! | E1: =UPDATE | J1: SCREENER.IN
A3: Narration | B3: ='Data Sheet'!B81 -> 0 | C3: ='Data Sheet'!C81 -> 0 | D3: ='Data Sheet'!D81 -> 43190 | E3: ='Data Sheet'!E81 -> 43555 | F3: ='Data Sheet'!F81 -> 43921 | G3: ='Data Sheet'!G81 -> 44286 | H3: ='Data Sheet'!H81 -> 44651 | I3: ='Data Sheet'!I81 -> 45016 | ... K3: ='Data Sheet'!K81 -> 45747
A4: Cash from Operating Activity | B4: ='Data Sheet'!B82 -> 0 | C4: ='Data Sheet'!C82 -> 0 | D4: ='Data Sheet'!D82 -> -79.38 | E4: ='Data Sheet'!E82 -> -99.73 | F4: ='Data Sheet'!F82 -> 6.15 | G4: ='Data Sheet'!G82 -> 133.18 | H4: ='Data Sheet'!H82 -> -353.96 | I4: ='Data Sheet'!I82 -> -140.24 | ... K4: ='Data Sheet'!K82 -> 466.63
A5: Cash from Investing Activity | B5: ='Data Sheet'!B83 -> 0 | C5: ='Data Sheet'!C83 -> 0 | D5: ='Data Sheet'!D83 -> 30.57 | E5: ='Data Sheet'!E83 -> -161.94 | F5: ='Data Sheet'!F83 -> 14.91 | G5: ='Data Sheet'!G83 -> -129.74 | H5: ='Data Sheet'!H83 -> -602.79 | I5: ='Data Sheet'!I83 -> 139.58 | ... K5: ='Data Sheet'!K83 -> -205.43
A6: Cash from Financing Activity | B6: ='Data Sheet'!B84 -> 0 | C6: ='Data Sheet'!C84 -> 0 | D6: ='Data Sheet'!D84 -> 81.94 | E6: ='Data Sheet'!E84 -> 235.69 | F6: ='Data Sheet'!F84 -> 68.72 | G6: ='Data Sheet'!G84 -> -37.72 | H6: ='Data Sheet'!H84 -> 927.01 | I6: ='Data Sheet'!I84 -> 4.87 | ... K6: ='Data Sheet'!K84 -> -212.04
A7: Net Cash Flow | B7: ='Data Sheet'!B85 -> 0 | C7: ='Data Sheet'!C85 -> 0 | D7: ='Data Sheet'!D85 -> 33.13 | E7: ='Data Sheet'!E85 -> -25.98 | F7: ='Data Sheet'!F85 -> 89.78 | G7: ='Data Sheet'!G85 -> -34.28 | H7: ='Data Sheet'!H85 -> -29.74 | I7: ='Data Sheet'!I85 -> 4.2 | ... K7: ='Data Sheet'!K85 -> 49.16

Sheet Data Sheet
A1: COMPANY NAME | B1: FSN E-COMMERCE VENTURES LTD | E1: =IF(B2<>B3, "A NEW VERSION OF THE WORKSHEET IS AVAILABLE", "")
A2: LATEST VERSION | B2: 2.1 | E2: PLEASE DO NOT MAKE ANY CHANGES TO THIS SHEET
A3: CURRENT VERSION | B3: 2.1
A5: META
A6: Number of shares | B6: =IF(B9>0, B9/B8, 0) -> 286.33824
A7: Face Value | B7: 1
A8: Current Price | B8: 269.66
A9: Market Capitalization | B9: 77213.97
A15: PROFIT & LOSS
A16: Report Date | D16: 43190 | E16: 43555 | F16: 43921 | G16: 44286 | H16: 44651 | I16: 45016 | J16: 45382 | K16: 45747
A17: Sales | D17: 574.36 | E17: 1111.39 | F17: 1767.53 | G17: 2440.9 | H17: 3773.94 | I17: 5143.8 | J17: 6385.63 | K17: 7949.82
A18: Raw Material Cost | D18: 436.16 | E18: 785.48 | F18: 1196.09 | G18: 1533.85 | H18: 2492.14 | I18: 3007.42 | J18: 3846.79 | K18: 4691.18
A19: Change in Inventory | D19: 59.93 | E19: 125.21 | F19: 181.88 | G19: 41.27 | H19: 362.13 | I19: 141.74 | J19: 200.4 | K19: 218.52
A20: Power and Fuel | D20: 0.6 | E20: 2.09 | F20: 4.62 | G20: 4.4 | H20: 6.64 | I20: 14.99 | J20: 20.68 | K20: 25.83
A21: Other Mfr. Exp | D21: 27.29 | E21: 48.09 | F21: 70.75 | G21: 137.03 | H21: 233.28 | I21: 199.27 | J21: 188.75 | K21: 216.21
A22: Employee Cost | D22: 54.93 | E22: 117.3 | F22: 195.63 | G22: 233.37 | H22: 327.57 | I22: 493.26 | J22: 566.26 | K22: 667.59
A23: Selling and admin | D23: 139.22 | E23: 253.12 | F23: 387.59 | G23: 389.05 | H23: 886.55 | I23: 1300.56 | J23: 1591.29 | K23: 2071.9
A24: Other Expenses | D24: 2.7 | E24: 9.66 | F24: 11.73 | G24: 26.23 | H24: 25.84 | I24: 12.98 | J24: 25.38 | K24: 20.85
A25: Other Income | D25: 3.72 | E25: 4.99 | F25: 10.32 | G25: 11.76 | H25: 26.97 | I25: 30.21 | J25: 29.94 | K25: 27.26
A26: Depreciation | D26: 7.4 | E26: 30.88 | F26: 59.51 | G26: 71.59 | H26: 96.41 | I26: 173.26 | J26: 224.23 | K26: 266.4
A27: Interest | D27: 7.16 | E27: 26.69 | F27: 46.24 | G27: 32.29 | H27: 47.3 | I27: 75.62 | J27: 83.56 | K27: 108.19
... A30: Net profit | D30: -28.18 | E30: -24.52 | F30: -16.61 | G30: 61.55 | H30: 41.08 | I30: 19.26 | J30: 32.27 | K30: 66.08
A31: Dividend Amount
A40: Quarters
A41: Report Date | B41: 45199 | C41: 45291 | D41: 45382 | E41: 45473 | F41: 45565 | G41: 45657 | H41: 45747 | I41: 45838 | J41: 45930 | K41: 46022
A42: Sales | B42: 1507.02 | C42: 1788.8 | D42: 1667.98 | E42: 1746.11 | F42: 1874.74 | G42: 2267.21 | H42: 2061.76 | I42: 2154.94 | J42: 2345.98 | K42: 2873.26
A43: Expenses | B43: 1426.39 | C43: 1690.02 | D43: 1574.7 | E43: 1649.99 | F43: 1771.08 | G43: 2126.43 | H43: 1928.41 | I43: 2014.26 | J43: 2187.03 | K43: 2643.5
A44: Other Income | B44: 8.57 | C44: 7.58 | D44: 7.06 | E44: 7.33 | F44: 5.45 | G44: 5.53 | H44: 8.95 | I44: 9.33 | J44: 6.99 | K44: -10.1
A45: Depreciation | B45: 54.64 | C45: 58.03 | D45: 59.65 | E45: 60.06 | F45: 63.62 | G45: 69.82 | H45: 72.9 | I45: 76.14 | J45: 79.09 | K45: 80.88
A46: Interest | B46: 21.31 | C46: 21.84 | D46: 21.13 | E46: 21.31 | F46: 24.23 | G46: 31.93 | H46: 29.85 | I46: 30.16 | J46: 31.47 | K46: 29.16
A47: Profit before tax | B47: 13.25 | C47: 26.49 | D47: 19.56 | E47: 22.08 | F47: 21.26 | G47: 44.56 | H47: 39.55 | I47: 43.71 | J47: 55.38 | K47: 109.62
A48: Tax | B48: 3.97 | C48: 8.26 | D48: 9.83 | E48: 7.84 | F48: 7.82 | G48: 17.59 | H48: 20.5 | I48: 19.24 | J48: 22.4 | K48: 41.88
A49: Net profit | B49: 5.85 | C49: 16.19 | D49: 6.93 | E49: 9.64 | F49: 10.04 | G49: 26.12 | H49: 20.28 | I49: 23.32 | J49: 34.43 | K49: 63.31
A50: Operating Profit | B50: 80.63 | C50: 98.78 | D50: 93.28 | E50: 96.12 | F50: 103.66 | G50: 140.78 | H50: 133.35 | I50: 140.68 | J50: 158.95 | K50: 229.76
A55: BALANCE SHEET
A56: Report Date | D56: 43190 | E56: 43555 | F56: 43921 | G56: 44286 | H56: 44651 | I56: 45016 | J56: 45382 | K56: 45747
A57: Equity Share Capital | D57: 13.56 | E57: 14.24 | F57: 14.55 | G57: 15.06 | H57: 47.41 | I57: 285.25 | J57: 285.6 | K57: 285.93
A58: Reserves | D58: 108.03 | E58: 216.32 | F58: 307.4 | G58: 474.51 | H58: 1292.49 | I58: 1092.77 | J58: 976.63 | K58: 1015.35
A59: Borrowings | D59: 83.05 | E59: 310.47 | F59: 412.77 | G59: 333 | H59: 592.62 | I59: 798.5 | J59: 969.49 | K59: 1320.59
A60: Other Liabilities | D60: 148.5 | E60: 234.62 | F60: 389.76 | G60: 479.37 | H60: 713.52 | I60: 773.45 | J60: 1168.91 | K60: 1357.66
...
